<?xml version="1.0"?>
<robot name="simple_2dof_arm">

  <!-- Base Link -->
  <link name="base_link">
    <visual>
      <geometry>
        <box size="0.1 0.1 0.1"/>
      </geometry>
      <origin xyz="0 0 0.05" rpy="0 0 0"/>
      <material name="gray"/>
    </visual>
  </link>

 <!-- Link 1 -->
<link name="link1">
  <visual>
    <geometry>
      <cylinder length="0.5" radius="0.05"/>
    </geometry>
    <origin xyz="0 0 0.25" rpy="0 0 0"/>
    <material name="blue"/>
  </visual>
  <collision>
    <geometry>
      <cylinder length="0.5" radius="0.05"/>
    </geometry>
    <origin xyz="0 0 0.25" rpy="0 0 0"/>
  </collision>
</link>

<!-- Link 2 -->
<link name="link2">
  <visual>
    <geometry>
      <cylinder length="0.4" radius="0.04"/>
    </geometry>
    <!-- Yeh position ab link1 ke andar aa raha hai -->
    <origin xyz="0 0 0.2"/>

    <material name="green"/>
  </visual>
  <collision>
    <geometry>
      <cylinder length="0.4" radius="0.04"/>
    </geometry>
    <origin xyz="0 0 0.2"/>

  </collision>
</link>


   <joint name="joint1" type="revolute">
    <parent link="base_link"/>
    <child link="link1"/>
    <origin xyz="0 0 0.1" rpy="0 0 0"/>
    <axis xyz="0 0 1"/>
    <limit lower="-3.14" upper="3.14" effort="1.0" velocity="1.0"/>
  </joint>

  <!-- Joint 2 (revolute) -->
  <joint name="joint2" type="revolute">
    <parent link="link1"/>
    <child link="link2"/>
    <origin xyz="0 0 0.5" rpy="0 0 0"/>
    <axis xyz="0 1 0"/>
    <limit lower="-1.57" upper="1.57" effort="1.0" velocity="1.0"/>
  </joint>

</robot>
